Traceback (most recent call last):
  File "/opt/anaconda3/envs/napari-env/lib/python3.8/site-packages/jupyter_cache/executors/utils.py", line 51, in single_nb_execution
    executenb(
  File "/opt/anaconda3/envs/napari-env/lib/python3.8/site-packages/nbclient/client.py", line 1117, in execute
    return NotebookClient(nb=nb, resources=resources, km=km, **kwargs).execute()
  File "/opt/anaconda3/envs/napari-env/lib/python3.8/site-packages/nbclient/util.py", line 78, in wrapped
    return just_run(coro(*args, **kwargs))
  File "/opt/anaconda3/envs/napari-env/lib/python3.8/site-packages/nbclient/util.py", line 57, in just_run
    return loop.run_until_complete(coro)
  File "/opt/anaconda3/envs/napari-env/lib/python3.8/asyncio/base_events.py", line 616, in run_until_complete
    return future.result()
  File "/opt/anaconda3/envs/napari-env/lib/python3.8/site-packages/nbclient/client.py", line 558, in async_execute
    await self.async_execute_cell(
  File "/opt/anaconda3/envs/napari-env/lib/python3.8/site-packages/nbclient/client.py", line 862, in async_execute_cell
    self._check_raise_for_error(cell, exec_reply)
  File "/opt/anaconda3/envs/napari-env/lib/python3.8/site-packages/nbclient/client.py", line 765, in _check_raise_for_error
    raise CellExecutionError.from_cell_and_msg(cell, exec_reply_content)
nbclient.exceptions.CellExecutionError: An error occurred while executing the following cell:
------------------
import napari
from napari.utils import nbscreenshot
from skimage import data

viewer = napari.view_image(data.cells3d(), channel_axis=1, name=["membrane", "nuclei"], colormap=["green", "magenta"])
viewer.dims.ndisplay = 3

#Reload the saved label layer if necessary
from tifffile import imread
viewer.add_labels(imread(file_name), name = 'seg')

from myst_nb import glue
s1 = nbscreenshot(viewer)
glue("s1",s1)
------------------

[0;31m---------------------------------------------------------------------------[0m
[0;31mNameError[0m                                 Traceback (most recent call last)
[0;32m/var/folders/mm/l16lrbmj5cvbqv_z7wsgsd0c0000gr/T/ipykernel_76301/744436039.py[0m in [0;36m<module>[0;34m[0m
[1;32m      8[0m [0;31m#Reload the saved label layer if necessary[0m[0;34m[0m[0;34m[0m[0;34m[0m[0m
[1;32m      9[0m [0;32mfrom[0m [0mtifffile[0m [0;32mimport[0m [0mimread[0m[0;34m[0m[0;34m[0m[0m
[0;32m---> 10[0;31m [0mviewer[0m[0;34m.[0m[0madd_labels[0m[0;34m([0m[0mimread[0m[0;34m([0m[0mfile_name[0m[0;34m)[0m[0;34m,[0m [0mname[0m [0;34m=[0m [0;34m'seg'[0m[0;34m)[0m[0;34m[0m[0;34m[0m[0m
[0m[1;32m     11[0m [0;34m[0m[0m
[1;32m     12[0m [0;32mfrom[0m [0mmyst_nb[0m [0;32mimport[0m [0mglue[0m[0;34m[0m[0;34m[0m[0m

[0;31mNameError[0m: name 'file_name' is not defined
NameError: name 'file_name' is not defined

